<?xml version="1.0" encoding="utf-8"?>
<robot name="simple4_urdf">
  <link name="world" />
  <link name="base_x_link" />
  <link name="base_y_link" />
  <link name="base_theta_link" />
  <link name="base_roll_link" />

  <joint name="base_x" type="prismatic">
    <origin xyz="0 0 0" rpy="0 0 0" />
    <parent link="world" />
    <child link="base_x_link" />
    <axis xyz="1 0 0" />
    <limit lower="-3.0" upper="3.0" effort="400.0" velocity="1.0" />
  </joint>

  <joint name="base_y" type="prismatic">
    <origin xyz="0 0 0" rpy="0 0 0" />
    <parent link="base_x_link" />
    <child link="base_y_link" />
    <axis xyz="0 1 0" />
    <limit lower="-3.0" upper="3.0" effort="400.0" velocity="1.0" />
  </joint>

  <joint name="base_theta" type="revolute">
    <origin xyz="0 0 0" rpy="0 0 0" />
    <parent link="base_y_link" />
    <child link="base_theta_link" />
    <axis xyz="0 0 1" />
    <limit lower="-3.141592653589793" upper="3.141592653589793" effort="150.0" velocity="1.57" />
  </joint>

  <!-- Align the exported simple4 body frame with the project convention: +X forward, +Z up. -->
  <joint name="base_roll_mount" type="fixed">
    <origin xyz="0 0 0" rpy="3.141592653589793 0 0" />
    <parent link="base_theta_link" />
    <child link="base_roll_link" />
  </joint>

  <link name="base_link">
    <inertial>
      <origin xyz="-4.7835E-16 0.0033916 -0.11843" rpy="0 0 0" />
      <mass value="26.422" />
      <inertia ixx="0.38775" ixy="1.3079E-17" ixz="-7.5307E-17" iyy="0.39408" iyz="-0.0017998" izz="0.53185" />
    </inertial>
    <visual>
      <origin xyz="0 0 0" rpy="0 0 0" />
      <geometry>
        <mesh filename="package://medipick_simple3_description/meshes/simple4_urdf/base_link.STL" />
      </geometry>
      <material name="base_blue">
        <color rgba="0.79216 0.81961 0.93333 1" />
      </material>
    </visual>
    <collision>
      <origin xyz="0 0 0" rpy="0 0 0" />
      <geometry>
        <mesh filename="package://medipick_simple3_description/meshes/simple4_urdf/base_link.STL" />
      </geometry>
    </collision>
  </link>

  <joint name="base_heading_mount" type="fixed">
    <origin xyz="0 0 0" rpy="0 0 1.5707963267948966" />
    <parent link="base_roll_link" />
    <child link="base_link" />
  </joint>

  <link name="raise_link">
    <inertial>
      <origin xyz="-0.028269 -0.065394 0.13893" rpy="0 0 0" />
      <mass value="1.4841" />
      <inertia ixx="0.021599" ixy="5.155E-05" ixz="8.8695E-06" iyy="0.020727" iyz="-3.8347E-06" izz="0.0033293" />
    </inertial>
    <visual>
      <origin xyz="0 0 0" rpy="0 0 0" />
      <geometry>
        <mesh filename="package://medipick_simple3_description/meshes/simple4_urdf/raise_link.STL" />
      </geometry>
      <material name="white">
        <color rgba="1 1 1 1" />
      </material>
    </visual>
    <collision>
      <origin xyz="0 0 0" rpy="0 0 0" />
      <geometry>
        <mesh filename="package://medipick_simple3_description/meshes/simple4_urdf/raise_link.STL" />
      </geometry>
    </collision>
  </link>

  <joint name="raise_joint" type="prismatic">
    <origin xyz="0 0 -0.939" rpy="0 0 0" />
    <parent link="base_link" />
    <child link="raise_link" />
    <axis xyz="0 0 -1" />
    <limit lower="0.0" upper="1.5" effort="100.0" velocity="0.2" />
  </joint>

  <link name="h1_link">
    <inertial>
      <origin xyz="-1.7347E-18 1.3878E-17 0.017" rpy="0 0 0" />
      <mass value="0.064115" />
      <inertia ixx="1.5798E-05" ixy="0" ixz="0" iyy="1.5798E-05" iyz="-5.1605E-38" izz="1.9243E-05" />
    </inertial>
    <visual>
      <origin xyz="0 0 0" rpy="0 0 0" />
      <geometry>
        <mesh filename="package://medipick_simple3_description/meshes/simple4_urdf/h1_link.STL" />
      </geometry>
      <material name="head_blue">
        <color rgba="0.79216 0.81961 0.93333 1" />
      </material>
    </visual>
    <collision>
      <origin xyz="0 0 0" rpy="0 0 0" />
      <geometry>
        <mesh filename="package://medipick_simple3_description/meshes/simple4_urdf/h1_link.STL" />
      </geometry>
    </collision>
  </link>

  <joint name="h1_joint" type="revolute">
    <origin xyz="0 -0.125 -0.0489" rpy="0 0 0" />
    <parent link="raise_link" />
    <child link="h1_link" />
    <axis xyz="0 0 1" />
    <limit lower="-3.141592653589793" upper="3.141592653589793" effort="10.0" velocity="3.14" />
  </joint>

  <link name="h2_link">
    <inertial>
      <origin xyz="0.017235 -0.013912 -0.010191" rpy="0 0 0" />
      <mass value="0.081692" />
      <inertia ixx="2.0082E-05" ixy="-3.1086E-10" ixz="-3.4953E-10" iyy="2.8989E-05" iyz="-1.7539E-07" izz="2.8574E-05" />
    </inertial>
    <visual>
      <origin xyz="0 0 0" rpy="0 0 0" />
      <geometry>
        <mesh filename="package://medipick_simple3_description/meshes/simple4_urdf/h2_link.STL" />
      </geometry>
      <material name="head_blue_2">
        <color rgba="0.79216 0.81961 0.93333 1" />
      </material>
    </visual>
    <collision>
      <origin xyz="0 0 0" rpy="0 0 0" />
      <geometry>
        <mesh filename="package://medipick_simple3_description/meshes/simple4_urdf/h2_link.STL" />
      </geometry>
    </collision>
  </link>

  <joint name="h2_joint" type="revolute">
    <origin xyz="-0.0181 0 -0.0485" rpy="0 0 0" />
    <parent link="h1_link" />
    <child link="h2_link" />
    <axis xyz="-1 0 0" />
    <limit lower="-3.141592653589793" upper="3.141592653589793" effort="10.0" velocity="3.14" />
  </joint>

  <link name="r1_link">
    <inertial>
      <origin xyz="0.046716 -0.0017583 3.3837E-05" rpy="0 0 0" />
      <mass value="0.15483" />
      <inertia ixx="0.0005363" ixy="2.1638E-05" ixz="-5.2196E-07" iyy="0.00083204" iyz="-9.3878E-08" izz="0.00069919" />
    </inertial>
    <visual>
      <origin xyz="0 0 0" rpy="0 0 0" />
      <geometry>
        <mesh filename="package://medipick_simple3_description/meshes/simple4_urdf/r1_link.STL" />
      </geometry>
      <material name="arm_blue_1">
        <color rgba="0.79216 0.81961 0.93333 1" />
      </material>
    </visual>
    <collision>
      <origin xyz="0 0 0" rpy="0 0 0" />
      <geometry>
        <mesh filename="package://medipick_simple3_description/meshes/simple4_urdf/r1_link.STL" />
      </geometry>
    </collision>
  </link>

  <joint name="r1_joint" type="revolute">
    <origin xyz="0.061 -0.125 0.064068" rpy="0 0 0" />
    <parent link="raise_link" />
    <child link="r1_link" />
    <axis xyz="1 0 0" />
    <limit lower="-6.283185307179586" upper="6.283185307179586" effort="30.0" velocity="2.09" />
  </joint>

  <link name="r2_link">
    <inertial>
      <origin xyz="0.069086 0.046887 -0.00040143" rpy="0 0 0" />
      <mass value="1.2587" />
      <inertia ixx="0.0042981" ixy="0.00041195" ixz="1.455E-05" iyy="0.0056991" iyz="-2.3891E-06" izz="0.0067954" />
    </inertial>
    <visual>
      <origin xyz="0 0 0" rpy="0 0 0" />
      <geometry>
        <mesh filename="package://medipick_simple3_description/meshes/simple4_urdf/r2_link.STL" />
      </geometry>
      <material name="arm_blue_2">
        <color rgba="0.79216 0.81961 0.93333 1" />
      </material>
    </visual>
    <collision>
      <origin xyz="0 0 0" rpy="0 0 0" />
      <geometry>
        <mesh filename="package://medipick_simple3_description/meshes/simple4_urdf/r2_link.STL" />
      </geometry>
    </collision>
  </link>

  <joint name="r2_joint" type="revolute">
    <origin xyz="0.0755 -0.036 0" rpy="0 0 0" />
    <parent link="r1_link" />
    <child link="r2_link" />
    <axis xyz="0 1 0" />
    <limit lower="-6.283185307179586" upper="6.283185307179586" effort="30.0" velocity="2.09" />
  </joint>

  <link name="r3_link">
    <inertial>
      <origin xyz="0.10805 -0.012352 -0.00062816" rpy="0 0 0" />
      <mass value="2.1071" />
      <inertia ixx="0.0041888" ixy="-0.00064087" ixz="3.0605E-05" iyy="0.010796" iyz="3.7257E-06" izz="0.009453" />
    </inertial>
    <visual>
      <origin xyz="0 0 0" rpy="0 0 0" />
      <geometry>
        <mesh filename="package://medipick_simple3_description/meshes/simple4_urdf/r3_link.STL" />
      </geometry>
      <material name="arm_white_1">
        <color rgba="1 1 1 1" />
      </material>
    </visual>
    <collision>
      <origin xyz="0 0 0" rpy="0 0 0" />
      <geometry>
        <mesh filename="package://medipick_simple3_description/meshes/simple4_urdf/r3_link.STL" />
      </geometry>
    </collision>
  </link>

  <joint name="r3_joint" type="revolute">
    <origin xyz="0.1511 0.036 -0.00087844" rpy="0 0 0" />
    <parent link="r2_link" />
    <child link="r3_link" />
    <axis xyz="-0.99998 0 0.0058136" />
    <limit lower="-6.283185307179586" upper="6.283185307179586" effort="30.0" velocity="2.09" />
  </joint>

  <link name="r4_link">
    <inertial>
      <origin xyz="0.12555 0.014227 -0.00072991" rpy="0 0 0" />
      <mass value="1.2673" />
      <inertia ixx="0.0021483" ixy="-0.00058443" ixz="1.641E-05" iyy="0.0049153" iyz="3.398E-06" izz="0.0049708" />
    </inertial>
    <visual>
      <origin xyz="0 0 0" rpy="0 0 0" />
      <geometry>
        <mesh filename="package://medipick_simple3_description/meshes/simple4_urdf/r4_link.STL" />
      </geometry>
      <material name="arm_white_2">
        <color rgba="1 1 1 1" />
      </material>
    </visual>
    <collision>
      <origin xyz="0 0 0" rpy="0 0 0" />
      <geometry>
        <mesh filename="package://medipick_simple3_description/meshes/simple4_urdf/r4_link.STL" />
      </geometry>
    </collision>
  </link>

  <joint name="r4_joint" type="revolute">
    <origin xyz="0.1989 -0.03325 -0.0011563" rpy="0 0 0" />
    <parent link="r3_link" />
    <child link="r4_link" />
    <axis xyz="0 1 0" />
    <limit lower="-6.283185307179586" upper="6.283185307179586" effort="30.0" velocity="2.09" />
  </joint>

  <link name="r5_link">
    <inertial>
      <origin xyz="0.07315 -0.0069963 -0.00042692" rpy="0 0 0" />
      <mass value="0.43103" />
      <inertia ixx="0.00059159" ixy="-6.3356E-06" ixz="4.7455E-07" iyy="0.00092799" iyz="4.4066E-08" izz="0.00067569" />
    </inertial>
    <visual>
      <origin xyz="0 0 0" rpy="0 0 0" />
      <geometry>
        <mesh filename="package://medipick_simple3_description/meshes/simple4_urdf/r5_link.STL" />
      </geometry>
      <material name="arm_white_3">
        <color rgba="1 1 1 1" />
      </material>
    </visual>
    <collision>
      <origin xyz="0 0 0" rpy="0 0 0" />
      <geometry>
        <mesh filename="package://medipick_simple3_description/meshes/simple4_urdf/r5_link.STL" />
      </geometry>
    </collision>
  </link>

  <joint name="r5_joint" type="revolute">
    <origin xyz="0.22105 0.034118 -0.0012851" rpy="0 0 0" />
    <parent link="r4_link" />
    <child link="r5_link" />
    <axis xyz="-0.99998 0 0.0058136" />
    <limit lower="-6.283185307179586" upper="6.283185307179586" effort="30.0" velocity="2.09" />
  </joint>

  <link name="r6_link">
    <inertial>
      <origin xyz="0.025422 0.0039079 1.7452E-12" rpy="0 0 0" />
      <mass value="0.057274" />
      <inertia ixx="1.2004E-05" ixy="9.0672E-06" ixz="4.0496E-15" iyy="8.3059E-05" iyz="1.2612E-16" izz="8.2776E-05" />
    </inertial>
    <visual>
      <origin xyz="0 0 0" rpy="0 0 0" />
      <geometry>
        <mesh filename="package://medipick_simple3_description/meshes/simple4_urdf/r6_link.STL" />
      </geometry>
      <material name="arm_tip">
        <color rgba="0.89804 0.91765 0.92941 1" />
      </material>
    </visual>
    <collision>
      <origin xyz="0 0 0" rpy="0 0 0" />
      <geometry>
        <mesh filename="package://medipick_simple3_description/meshes/simple4_urdf/r6_link.STL" />
      </geometry>
    </collision>
  </link>

  <joint name="r6_joint" type="revolute">
    <origin xyz="0.077999 0.0235 -0.00045346" rpy="0 0 0" />
    <parent link="r5_link" />
    <child link="r6_link" />
    <axis xyz="0 -1 0" />
    <limit lower="-6.283185307179586" upper="6.283185307179586" effort="30.0" velocity="2.09" />
  </joint>

  <link name="sucker_link">
    <inertial>
      <origin xyz="-0.019014 2.9698E-15 -1.1102E-16" rpy="0 0 0" />
      <mass value="0.10089" />
      <inertia ixx="6.081E-06" ixy="3.0295E-18" ixz="-1.0507E-21" iyy="2.5551E-05" iyz="-7.3003E-31" izz="2.5551E-05" />
    </inertial>
    <visual>
      <origin xyz="0 0 0" rpy="0 0 0" />
      <geometry>
        <mesh filename="package://medipick_simple3_description/meshes/simple4_urdf/sucker_link.STL" />
      </geometry>
      <material name="tool_gray">
        <color rgba="0.61569 0.64314 0.67451 1" />
      </material>
    </visual>
    <collision>
      <origin xyz="0 0 0" rpy="0 0 0" />
      <geometry>
        <mesh filename="package://medipick_simple3_description/meshes/simple4_urdf/sucker_link.STL" />
      </geometry>
    </collision>
  </link>

  <joint name="sucker_joint" type="revolute">
    <origin xyz="0.1112 -0.0235 0" rpy="0 0 0" />
    <parent link="r6_link" />
    <child link="sucker_link" />
    <axis xyz="1 0 0" />
    <limit lower="-6.283185307179586" upper="6.283185307179586" effort="10.0" velocity="3.14" />
  </joint>

  <ros2_control name="MediPickSystem" type="system">
    <hardware>
      <plugin>mock_components/GenericSystem</plugin>
    </hardware>
    <joint name="base_x">
      <command_interface name="position" />
      <state_interface name="position">
        <param name="initial_value">0.0</param>
      </state_interface>
      <state_interface name="velocity" />
    </joint>
    <joint name="base_y">
      <command_interface name="position" />
      <state_interface name="position">
        <param name="initial_value">0.0</param>
      </state_interface>
      <state_interface name="velocity" />
    </joint>
    <joint name="base_theta">
      <command_interface name="position" />
      <state_interface name="position">
        <param name="initial_value">0.0</param>
      </state_interface>
      <state_interface name="velocity" />
    </joint>
    <joint name="raise_joint">
      <command_interface name="position" />
      <state_interface name="position">
        <param name="initial_value">0.0</param>
      </state_interface>
      <state_interface name="velocity" />
    </joint>
    <joint name="r1_joint">
      <command_interface name="position" />
      <state_interface name="position">
        <param name="initial_value">0.10</param>
      </state_interface>
      <state_interface name="velocity" />
    </joint>
    <joint name="r2_joint">
      <command_interface name="position" />
      <state_interface name="position">
        <param name="initial_value">1.20</param>
      </state_interface>
      <state_interface name="velocity" />
    </joint>
    <joint name="r3_joint">
      <command_interface name="position" />
      <state_interface name="position">
        <param name="initial_value">-4.555309</param>
      </state_interface>
      <state_interface name="velocity" />
    </joint>
    <joint name="r4_joint">
      <command_interface name="position" />
      <state_interface name="position">
        <param name="initial_value">1.10</param>
      </state_interface>
      <state_interface name="velocity" />
    </joint>
    <joint name="r5_joint">
      <command_interface name="position" />
      <state_interface name="position">
        <param name="initial_value">0.45</param>
      </state_interface>
      <state_interface name="velocity" />
    </joint>
    <joint name="r6_joint">
      <command_interface name="position" />
      <state_interface name="position">
        <param name="initial_value">0.15</param>
      </state_interface>
      <state_interface name="velocity" />
    </joint>
    <joint name="sucker_joint">
      <command_interface name="position" />
      <state_interface name="position">
        <param name="initial_value">0.0</param>
      </state_interface>
      <state_interface name="velocity" />
    </joint>
    <joint name="h1_joint">
      <command_interface name="position" />
      <state_interface name="position">
        <param name="initial_value">0.0</param>
      </state_interface>
      <state_interface name="velocity" />
    </joint>
    <joint name="h2_joint">
      <command_interface name="position" />
      <state_interface name="position">
        <param name="initial_value">0.0</param>
      </state_interface>
      <state_interface name="velocity" />
    </joint>
  </ros2_control>
</robot>
